Workbook
Name A: #REF!
Name A: #REF!
Name A: #REF!
Name A: #REF!
Name A: #REF!
Name A: #REF!
Name A: #REF!
Name A: #REF!
Name A: #REF!
Name A: #REF!
Name A: #REF!
Name A: #REF!
Name A: #REF!
Name A: #REF!
Name A: #REF!
Name A: #REF!
Name A: #REF!
Name B: #REF!
Name B: #REF!
Name B: #REF!
Name B: #REF!
Name B: #REF!
Name B: #REF!
Name B: #REF!
Name B: #REF!
Name B: #REF!
Name B: #REF!
Name B: #REF!
Name B: #REF!
Name B: #REF!
Name B: #REF!
Name B: #REF!
Name B: #REF!
Name B: #REF!
Name FECHAINGRESO: #REF!
Name FECHAINGRESO: #REF!
Name FECHAINGRESO: #REF!
Name FECHAINGRESO: #REF!
Name FECHAINGRESO: #REF!
Name FECHAINGRESO: #REF!
Name FECHAINGRESO: #REF!
Name FECHAINGRESO: #REF!
Name FECHAINGRESO: #REF!
Name FECHAINGRESO: #REF!
Name FECHAINGRESO: #REF!
Name FECHAINGRESO: #REF!
Name FECHAINGRESO: #REF!
Name FECHAINGRESO: #REF!
Name FECHAINGRESO: #REF!
Name FECHAINGRESO: #REF!
Name FECHAINGRESO: #REF!
Name FECHAPAGO_MAT: #REF!
Name FECHAPAGO_MAT: #REF!
Name FECHAPAGO_MAT: #REF!
Name FECHAPAGO_MAT: #REF!
Name FECHAPAGO_MAT: #REF!
Name FECHAPAGO_MAT: #REF!
Name FECHAPAGO_MAT: #REF!
Name FECHAPAGO_MAT: #REF!
Name FECHAPAGO_MAT: #REF!

Sheet RESUMEN
A1: SF - PLOMERIA TOTAL | D1: 166000000
A2: Adelanto | D2: 15000000
A3: Saldo | D3: =D1-D2 -> 151000000
A5: De los cuales:
A6: PLOMERIA INTERIOR | D6: 103500000 | E6: /14 | F6: =D6/14 -> 7392857.1 | G6: /2 | H6: =F6/2 -> 3696428.6
A7: PLOMERIA EXTERIOR | D7: =D1-D6 -> 62500000
C9: TOTAL COMPLEJO | D9: POR MÓDULO
A10: INTERIOR TERMINADOS (12, 11, 10, 09, 08) | B10: 0.3 | C10: =D6*0.3 -> 31050000 | D10: =C10/5 -> 6210000
A11: INTERIOR X HACER (13, 07, 06, 05, 04, 03, 02, 01) | B11: 0.7 | C11: =D6*0.7 -> 72450000 | D11: =C11/8 -> 9056250
A13: RESUMEN DE PAGOS
A14: Adelanto | D14: =D2 -> 15000000
A15: Avance | D15: =SUM('M12'!F58+'M12'!G58+'M12'!H58+'M11'!F58+'M11'!G58+'M11'!H58+'M10'!F58+'M10'!G58+'M10'!H58) -> 6862050
A16: Pagado total | D16: =D14+D15 -> 21862050
A17: A pagar | D17: =(D6+D7)-D16 -> 144137950

Sheet PAGOS QUINCENALES
A1: SF - PAGOS TOTALES PLOMERÍA RODRIGO X QUINCENA
A4: MAYO | C4: JUNIO | E4: JULIO | G4: AGOSTO | I4: SEPTIEMBRE | K4: OCTUBRE | M4: NOVIEMBRE
A5: C1 | C5: C2 | E5: C3 | G5: C4 | I5: C5 | K5: C6 | M5: C7
A6: Q1 | B6: Q2 | C6: Q1 | D6: Q2 | E6: Q1 | F6: Q2 | G6: Q1 | H6: Q2 | I6: Q1 | J6: Q2 | K6: Q1 | L6: Q2 | M6: Q1 | N6: Q2
B7: =SUM('M12'!G58+'M11'!G58+'M10'!G58+'M09'!G58) -> 6210000 | C7: =SUM('M12'!H58+'M11'!H58+'M10'!H58+'M09'!H58) -> 652050 | D7: =SUM('M12'!I58+'M11'!I58+'M10'!I58+'M09'!I58) -> 589950 | E7: =SUM('M12'!J58+'M11'!J58+'M10'!J58+'M09'!J58) -> 0 | F7: =SUM('M12'!K58+'M11'!K58+'M10'!K58+'M09'!K58) -> 0
A9: DICIEMBRE | C9: ENERO | E9: FEBRERO | G9: MARZO | I9: ABRIL | K9: MAYO | M9: JUNIO
A10: C8 | C10: C9 | E10: C10 | G10: C11 | I10: C12 | K10: C13 | M10: C14
A11: Q1 | B11: Q2 | C11: Q1 | D11: Q2 | E11: Q1 | F11: Q2 | G11: Q3 | H11: Q4 | I11: Q5 | J11: Q6 | K11: Q7 | L11: Q8 | M11: Q9 | N11: Q10
A14: TOTAL CERTIFICADO | C14: =SUM(A7:N7,A12:N12) -> 7452000 | K14: RESTAN | M14: =('M12'!C3+'M11'!C3+'M10'!C3+'M09'!C3+'M08'!C3+'M07'!C3+'M06'!C3+'M05'!C3+'M13'!C3+'M04'!C3+'M03'!C3+'M02'!C3+'M01'!C3)-C14 -> 96048000

Sheet CASH FLOW 12,11,10,9,8
A1: SF - PLOMERÍA RODRIGO TERMINADOS (12,11.10,9,8)
A2: MES BASE ACTUALIZACIÓN | C2: 46113
A3: MONTO DE OBRA INICIAL | C3: =RESUMEN!D10 -> 6210000
A4: ANTICIPO | D4: =C4/C3 -> 0
F5: MAYO | H5: JUNIO | J5: JULIO | L5: AGOSTO | N5: SEPTIEMBRE | P5: OCTUBRE | R5: NOVIEMBRE | T5: DICIEMBRE | V5: ENERO | X5: FEBRERO | Z5: MARZO | AB5: ABRIL | AD5: MAYO | AF5: JUNIO
A6: ITEM | B6: DESCRIPCIÓN | C6: % ITEM | D6: MONTO TOTAL | E6: FINALIZADO | F6: C1 | H6: C2 | J6: C3 | L6: C4 | N6: C5 | P6: C6 | R6: C7 | T6: C8 | V6: C9 | X6: C10 | Z6: C11 | AB6: C12 | AD6: C13 | AF6: C14
A7: 1 | B7: AGUA | C7: =SUM(C8:C12) -> 0.25 | D7: =C7*C3 -> 1552500 | F7: Q1 | G7: Q2 | H7: Q1 | I7: Q2 | J7: Q1 | K7: Q2 | L7: Q1 | M7: Q2 | N7: Q1 | O7: Q2 | P7: Q1 | Q7: Q2 | R7: Q1 | S7: Q2 | T7: Q1 | U7: Q2 | V7: Q1 | W7: Q2 | X7: Q1 | Y7: Q2 | Z7: Q3 | AA7: Q4 | AB7: Q5 | AC7: Q6 | AD7: Q7 | AE7: Q8 | AF7: Q9 | AG7: Q10
A8: 1 | B8: 2/4 ambs | C8: 0.05 | E8: =SUM(F8:AG8) -> 0.05 | F8: 0.05 | AJ8: AGUA - 2 Ambientes
A9: 2 | B9: Acceso duplex | C9: 0.05 | E9: =SUM(F9:AG9) -> 0.05 | F9: 0.05 | AJ9: CLOACA - 2 Ambiente
A10: 3 | B10: Estar | C10: 0.05 | E10: =SUM(F10:AG10) -> 0.05 | G10: 0.05 | AJ10: AGUA - 4 Ambientes
A11: 4 | B11: Baño dormi 1 | C11: 0.05 | E11: =SUM(F11:AG11) -> 0.05 | G11: 0.05 | AJ11: CLOACA - 4 Ambiente
A12: 5 | B12: Baño dormi 2 | C12: 0.05 | E12: =SUM(F12:AG12) -> 0.05 | G12: 0.05 | AJ12: AGUA - Acceso y estar Duplex
AJ13: CLOACA - Acceso y estar Duplex
A14: 2 | B14: CLOACALES | C14: =SUM(C15:C19) -> 0.3 | D14: =C14*C3 -> 1863000 | AJ14: AGUA - Dormitorios
A15: 1 | B15: 2/4 ambs | C15: 0.1 | E15: =SUM(F15:AG15) -> 0.1 | F15: 0.1 | AJ15: CLOACA - Dormitorios
A16: 2 | B16: Acceso duplex | C16: 0.05 | E16: =SUM(F16:AG16) -> 0.05 | F16: 0.05 | AJ16: Gas
A17: 3 | B17: Estar | C17: 0.05 | E17: =SUM(F17:AG17) -> 0.05 | G17: 0.05 | AJ17: radiadores
A18: 4 | B18: Dormi 1 | C18: 0.05 | E18: =SUM(F18:AG18) -> 0.05 | G18: 0.05 | AJ18: Exteriores - caños en zanjeo ya hecho
A19: 5 | B19: Dormi 2 | C19: 0.05 | E19: =SUM(F19:AG19) -> 0.05 | G19: 0.05 | AJ19: Exteriores - pozos
A21: 3 | B21: PLUVIALES | C21: =SUM(C22:C26) -> 0.1 | D21: =C21*C3 -> 621000
A22: 1 | B22: 2/4 ambs | C22: 0.02 | E22: =SUM(F22:AG22) -> 0.02 | H22: 0.02
A23: 2 | B23: Acceso duplex | C23: 0.02 | E23: =SUM(F23:AG23) -> 0.02 | H23: 0.02
A24: 3 | B24: Estar | C24: 0.02 | E24: =SUM(F24:AG24) -> 0.02 | H24: 0.01 | K24: 0.01
A25: 4 | B25: Dormi 1 | C25: 0.02 | E25: =SUM(F25:AG25) -> 0.02 | H25: 0.01 | K25: 0.01
A26: 5 | B26: Dormi 2 | C26: 0.02 | E26: =SUM(F26:AG26) -> 0.02 | H26: 0.01 | K26: 0.01
A28: 4 | B28: COLOCACIÓN | C28: =SUM(C29:C33) -> 0.18 | D28: =C28*C3 -> 1117800
A29: 1 | B29: 2/4 ambs | C29: 0.04 | E29: =SUM(F29:AG29) -> 0.04 | M29: 0.02 | T29: 0.02
A30: 2 | B30: Acceso duplex | C30: 0.04 | E30: =SUM(F30:AG30) -> 0.04 | M30: 0.02 | T30: 0.02
A31: 3 | B31: Estar | C31: 0.04 | E31: =SUM(F31:AG31) -> 0.04 | M31: 0.02 | T31: 0.02
A32: 4 | B32: Dormi 1 | C32: 0.03 | E32: =SUM(F32:AG32) -> 0.03 | M32: 0.02 | T32: 0.01
A33: 5 | B33: Dormi 2 | C33: 0.03 | E33: =SUM(F33:AG33) -> 0.03 | M33: 0.02 | T33: 0.01
A35: 5 | B35: GAS | C35: =SUM(C36) -> 0.08 | D35: =C35*C3 -> 496800
A36: 1 | B36: General | C36: 0.08 | E36: =SUM(F36:AG36) -> 0.08 | I36: 0.04 | J36: 0.04
A38: 6 | B38: CALEFACCIÓN | C38: =SUM(C39:C43) -> 0.05 | D38: =C38*C3 -> 310500
A39: 1 | B39: 2/4 ambs | C39: 0.01 | E39: =SUM(F39:AG39) -> 0.01 | K39: 0.005 | T39: 0.005
A40: 2 | B40: Acceso duplex | C40: 0.01 | E40: =SUM(F40:AG40) -> 0.01 | K40: 0.005 | T40: 0.005
A41: 3 | B41: Estar | C41: 0.01 | E41: =SUM(F41:AG41) -> 0.01 | K41: 0.005 | T41: 0.005
A42: 4 | B42: Dormi 1 | C42: 0.01 | E42: =SUM(F42:AG42) -> 0.01 | K42: 0.005 | T42: 0.005
A43: 5 | B43: Dormi 2 | C43: 0.01 | E43: =SUM(F43:AG43) -> 0.01 | K43: 0.005 | T43: 0.005
A45: 7 | B45: ESPECIALES | C45: =SUM(C46:C49) -> 0.04 | D45: =C45*C3 -> 248400
...

Sheet CASH FLOW 13,7,6,5,4,3,2,1
A1: SF - PLOMERÍA RODRIGO NUEVOS (13,7,6,5,4,3,2,1)
A2: MES BASE ACTUALIZACIÓN | C2: 46113
A3: MONTO DE OBRA INICIAL | C3: =RESUMEN!D11 -> 9056250
A4: ANTICIPO | D4: =C4/C3 -> 0
F5: MAYO | H5: JUNIO | J5: JULIO | L5: AGOSTO | N5: SEPTIEMBRE | P5: OCTUBRE | R5: NOVIEMBRE | T5: DICIEMBRE | V5: ENERO | X5: FEBRERO | Z5: MARZO | AB5: ABRIL | AD5: MAYO | AF5: JUNIO
A6: ITEM | B6: DESCRIPCIÓN | C6: % ITEM | D6: MONTO TOTAL | E6: FINALIZADO | F6: C1 | H6: C2 | J6: C3 | L6: C4 | N6: C5 | P6: C6 | R6: C7 | T6: C8 | V6: C9 | X6: C10 | Z6: C11 | AB6: C12 | AD6: C13 | AF6: C14
A7: 1 | B7: AGUA | C7: =SUM(C8:C12) -> 0.25 | D7: =C7*C3 -> 2264062.5 | F7: Q1 | G7: Q2 | H7: Q1 | I7: Q2 | J7: Q1 | K7: Q2 | L7: Q1 | M7: Q2 | N7: Q1 | O7: Q2 | P7: Q1 | Q7: Q2 | R7: Q1 | S7: Q2 | T7: Q1 | U7: Q2 | V7: Q1 | W7: Q2 | X7: Q1 | Y7: Q2 | Z7: Q3 | AA7: Q4 | AB7: Q5 | AC7: Q6 | AD7: Q7 | AE7: Q8 | AF7: Q9 | AG7: Q10
A8: 1 | B8: 2/4 ambs | C8: 0.05 | E8: =SUM(F8:AG8) -> 0.05 | F8: 0.025 | N8: 0.025 | AJ8: AGUA - 2 Ambientes
A9: 2 | B9: Acceso duplex | C9: 0.05 | E9: =SUM(F9:AG9) -> 0.05 | G9: 0.025 | N9: 0.025 | AJ9: CLOACA - 2 Ambiente
A10: 3 | B10: Estar | C10: 0.05 | E10: =SUM(F10:AG10) -> 0.05 | H10: 0.025 | O10: 0.025 | AJ10: AGUA - 4 Ambientes
A11: 4 | B11: Baño dormi 1 | C11: 0.05 | E11: =SUM(F11:AG11) -> 0.05 | I11: 0.025 | O11: 0.025 | AJ11: CLOACA - 4 Ambiente
A12: 5 | B12: Baño dormi 2 | C12: 0.05 | E12: =SUM(F12:AG12) -> 0.05 | J12: 0.025 | O12: 0.025 | AJ12: AGUA - Acceso y estar Duplex
AJ13: CLOACA - Acceso y estar Duplex
A14: 2 | B14: CLOACALES | C14: =SUM(C15:C19) -> 0.3 | D14: =C14*C3 -> 2716875 | AJ14: AGUA - Dormitorios
A15: 1 | B15: 2/4 ambs | C15: 0.1 | E15: =SUM(F15:AG15) -> 0.1 | F15: 0.05 | N15: 0.05 | AJ15: CLOACA - Dormitorios
A16: 2 | B16: Acceso duplex | C16: 0.05 | E16: =SUM(F16:AG16) -> 0.05 | G16: 0.025 | N16: 0.025 | AJ16: Gas
A17: 3 | B17: Estar | C17: 0.05 | E17: =SUM(F17:AG17) -> 0.05 | H17: 0.025 | O17: 0.025 | AJ17: radiadores
A18: 4 | B18: Dormi 1 | C18: 0.05 | E18: =SUM(F18:AG18) -> 0.05 | I18: 0.025 | O18: 0.025 | AJ18: Exteriores - caños en zanjeo ya hecho
A19: 5 | B19: Dormi 2 | C19: 0.05 | E19: =SUM(F19:AG19) -> 0.05 | J19: 0.025 | O19: 0.025 | AJ19: Exteriores - pozos
A21: 3 | B21: PLUVIALES | C21: =SUM(C22:C26) -> 0.1 | D21: =C21*C3 -> 905625
A22: 1 | B22: 2/4 ambs | C22: 0.02 | E22: =SUM(F22:AG22) -> 0.02 | F22: 0.01 | P22: 0.01
A23: 2 | B23: Acceso duplex | C23: 0.02 | E23: =SUM(F23:AG23) -> 0.02 | G23: 0.01 | P23: 0.01
A24: 3 | B24: Estar | C24: 0.02 | E24: =SUM(F24:AG24) -> 0.02 | H24: 0.01 | S24: 0.01
A25: 4 | B25: Dormi 1 | C25: 0.02 | E25: =SUM(F25:AG25) -> 0.02 | I25: 0.01 | S25: 0.01
A26: 5 | B26: Dormi 2 | C26: 0.02 | E26: =SUM(F26:AG26) -> 0.02 | J26: 0.01 | S26: 0.01
A28: 4 | B28: COLOCACIÓN | C28: =SUM(C29:C33) -> 0.18 | D28: =C28*C3 -> 1630125
A29: 1 | B29: 2/4 ambs | C29: 0.04 | E29: =SUM(F29:AG29) -> 0.04 | T29: 0.02 | AB29: 0.02
A30: 2 | B30: Acceso duplex | C30: 0.04 | E30: =SUM(F30:AG30) -> 0.04 | T30: 0.02 | AB30: 0.02
A31: 3 | B31: Estar | C31: 0.04 | E31: =SUM(F31:AG31) -> 0.04 | T31: 0.02 | AB31: 0.02
A32: 4 | B32: Dormi 1 | C32: 0.03 | E32: =SUM(F32:AG32) -> 0.03 | T32: 0.01 | AB32: 0.02
A33: 5 | B33: Dormi 2 | C33: 0.03 | E33: =SUM(F33:AG33) -> 0.03 | T33: 0.015 | AB33: 0.015
A35: 5 | B35: GAS | C35: =SUM(C36) -> 0.08 | D35: =C35*C3 -> 724500
A36: 1 | B36: General | C36: 0.08 | E36: =SUM(F36:AG36) -> 0.08 | Q36: 0.04 | R36: 0.04
A38: 6 | B38: CALEFACCIÓN | C38: =SUM(C39:C43) -> 0.05 | D38: =C38*C3 -> 452812.5
A39: 1 | B39: 2/4 ambs | C39: 0.01 | E39: =SUM(F39:AG39) -> 0.01 | S39: 0.005 | AB39: 0.005
A40: 2 | B40: Acceso duplex | C40: 0.01 | E40: =SUM(F40:AG40) -> 0.01 | S40: 0.005 | AB40: 0.005
A41: 3 | B41: Estar | C41: 0.01 | E41: =SUM(F41:AG41) -> 0.01 | S41: 0.005 | AB41: 0.005
A42: 4 | B42: Dormi 1 | C42: 0.01 | E42: =SUM(F42:AG42) -> 0.01 | S42: 0.005 | AB42: 0.005
A43: 5 | B43: Dormi 2 | C43: 0.01 | E43: =SUM(F43:AG43) -> 0.01 | S43: 0.005 | AB43: 0.005
A45: 7 | B45: ESPECIALES | C45: =SUM(C46:C49) -> 0.04 | D45: =C45*C3 -> 362250
...

Sheet PRUEBAS
B1: PRUEBAS
A2: MES BASE ACTUALIZACIÓN | C2: 46113
A3: MONTO DE OBRA INICIAL | C3: =RESUMEN!D10 -> 6210000
A4: ANTICIPO | D4: =C4/C3 -> 0
F5: MAYO | H5: JUNIO | J5: JULIO | L5: AGOSTO | N5: SEPTIEMBRE | P5: OCTUBRE | R5: NOVIEMBRE | T5: DICIEMBRE | V5: ENERO | X5: FEBRERO | Z5: MARZO | AB5: ABRIL | AD5: MAYO | AF5: JUNIO
A6: ITEM | B6: DESCRIPCIÓN | C6: % ITEM | D6: MONTO TOTAL | E6: FINALIZADO | F6: C1 | H6: C2 | J6: C3 | L6: C4 | N6: C5 | P6: C6 | R6: C7 | T6: C8 | V6: C9 | X6: C10 | Z6: C11 | AB6: C12 | AD6: C13 | AF6: C14
A7: 1 | B7: AGUA | C7: =SUM(C8:C12) -> 0.25 | D7: =C7*C3 -> 1552500 | F7: Q1 | G7: Q2 | H7: Q1 | I7: Q2 | J7: Q1 | K7: Q2 | L7: Q1 | M7: Q2 | N7: Q1 | O7: Q2 | P7: Q1 | Q7: Q2 | R7: Q1 | S7: Q2 | T7: Q1 | U7: Q2 | V7: Q1 | W7: Q2 | X7: Q1 | Y7: Q2 | Z7: Q3 | AA7: Q4 | AB7: Q5 | AC7: Q6 | AD7: Q7 | AE7: Q8 | AF7: Q9 | AG7: Q10
A8: 1 | B8: 2/4 ambs | C8: 0.05 | E8: =SUM(F8:AG8) -> 0 | AJ8: AGUA - 2 Ambientes
A9: 2 | B9: Acceso duplex | C9: 0.05 | E9: =SUM(F9:AG9) -> 0 | AJ9: CLOACA - 2 Ambiente
A10: 3 | B10: Estar | C10: 0.05 | E10: =SUM(F10:AG10) -> 0 | AJ10: AGUA - 4 Ambientes
A11: 4 | B11: Baño dormi 1 | C11: 0.05 | E11: =SUM(F11:AG11) -> 0 | AJ11: CLOACA - 4 Ambiente
A12: 5 | B12: Baño dormi 2 | C12: 0.05 | E12: =SUM(F12:AG12) -> 0 | AJ12: AGUA - Acceso y estar Duplex
AJ13: CLOACA - Acceso y estar Duplex
A14: 2 | B14: CLOACALES | C14: =SUM(C15:C19) -> 0.3 | D14: =C14*C3 -> 1863000 | AJ14: AGUA - Dormitorios
A15: 1 | B15: 2/4 ambs | C15: 0.1 | E15: =SUM(F15:AG15) -> 0.1 | F15: 0.1 | AJ15: CLOACA - Dormitorios
A16: 2 | B16: Acceso duplex | C16: 0.05 | E16: =SUM(F16:AG16) -> 0.05 | F16: 0.05 | AJ16: Gas
A17: 3 | B17: Estar | C17: 0.05 | E17: =SUM(F17:AG17) -> 0 | AJ17: radiadores
A18: 4 | B18: Dormi 1 | C18: 0.05 | E18: =SUM(F18:AG18) -> 0 | AJ18: Exteriores - caños en zanjeo ya hecho
A19: 5 | B19: Dormi 2 | C19: 0.05 | E19: =SUM(F19:AG19) -> 0 | AJ19: Exteriores - pozos
A21: 3 | B21: PLUVIALES | C21: =SUM(C22:C26) -> 0.1 | D21: =C21*C3 -> 621000
A22: 1 | B22: 2/4 ambs | C22: 0.02 | E22: =SUM(F22:AG22) -> 0.04 | F22: 0.02 | G22: 0.02
A23: 2 | B23: Acceso duplex | C23: 0.02 | E23: =SUM(F23:AG23) -> 0.04 | F23: 0.02 | G23: 0.02
A24: 3 | B24: Estar | C24: 0.02 | E24: =SUM(F24:AG24) -> 0
A25: 4 | B25: Dormi 1 | C25: 0.02 | E25: =SUM(F25:AG25) -> 0
A26: 5 | B26: Dormi 2 | C26: 0.02 | E26: =SUM(F26:AG26) -> 0.02 | G26: 0.02
A28: 4 | B28: COLOCACIÓN | C28: =SUM(C29:C33) -> 0.18 | D28: =C28*C3 -> 1117800
A29: 1 | B29: 2/4 ambs | C29: 0.04 | E29: =SUM(F29:AG29) -> 0
A30: 2 | B30: Acceso duplex | C30: 0.04 | E30: =SUM(F30:AG30) -> 0
A31: 3 | B31: Estar | C31: 0.04 | E31: =SUM(F31:AG31) -> 0
A32: 4 | B32: Dormi 1 | C32: 0.03 | E32: =SUM(F32:AG32) -> 0
A33: 5 | B33: Dormi 2 | C33: 0.03 | E33: =SUM(F33:AG33) -> 0
A35: 5 | B35: GAS | C35: =SUM(C36) -> 0.08 | D35: =C35*C3 -> 496800
A36: 1 | B36: General | C36: 0.08 | E36: =SUM(F36:AG36) -> 0
A38: 6 | B38: CALEFACCIÓN | C38: =SUM(C39:C43) -> 0.05 | D38: =C38*C3 -> 310500
A39: 1 | B39: 2/4 ambs | C39: 0.01 | E39: =SUM(F39:AG39) -> 0
A40: 2 | B40: Acceso duplex | C40: 0.01 | E40: =SUM(F40:AG40) -> 0
A41: 3 | B41: Estar | C41: 0.01 | E41: =SUM(F41:AG41) -> 0
A42: 4 | B42: Dormi 1 | C42: 0.01 | E42: =SUM(F42:AG42) -> 0
A43: 5 | B43: Dormi 2 | C43: 0.01 | E43: =SUM(F43:AG43) -> 0
A45: 7 | B45: ESPECIALES | C45: =SUM(C46:C49) -> 0.04 | D45: =C45*C3 -> 248400
...

Sheet M12
B1: SF - PLOMERÍA RODRIGO M12
A2: MES BASE ACTUALIZACIÓN | C2: 46113
A3: MONTO DE OBRA INICIAL | C3: =RESUMEN!D10 -> 6210000
A4: ANTICIPO | D4: =C4/C3 -> 0
F5: MAYO | H5: JUNIO | J5: JULIO | L5: AGOSTO | N5: SEPTIEMBRE | P5: OCTUBRE | R5: NOVIEMBRE | T5: DICIEMBRE | V5: ENERO | X5: FEBRERO | Z5: MARZO | AB5: ABRIL | AD5: MAYO | AF5: JUNIO
A6: ITEM | B6: DESCRIPCIÓN | C6: % ITEM | D6: MONTO TOTAL | E6: FINALIZADO | F6: C1 | H6: C2 | J6: C3 | L6: C4 | N6: C5 | P6: C6 | R6: C7 | T6: C8 | V6: C9 | X6: C10 | Z6: C11 | AB6: C12 | AD6: C13 | AF6: C14
A7: 1 | B7: AGUA | C7: =SUM(C8:C12) -> 0.25 | D7: =C7*C3 -> 1552500 | F7: Q1 | G7: Q2 | H7: Q1 | I7: Q2 | J7: Q1 | K7: Q2 | L7: Q1 | M7: Q2 | N7: Q1 | O7: Q2 | P7: Q1 | Q7: Q2 | R7: Q1 | S7: Q2 | T7: Q1 | U7: Q2 | V7: Q1 | W7: Q2 | X7: Q1 | Y7: Q2 | Z7: Q3 | AA7: Q4 | AB7: Q5 | AC7: Q6 | AD7: Q7 | AE7: Q8 | AF7: Q9 | AG7: Q10
A8: 1 | B8: 2/4 ambs | C8: 0.05 | E8: =SUM(F8:AG8) -> 0
A9: 2 | B9: Acceso duplex | C9: 0.05 | E9: =SUM(F9:AG9) -> 0
A10: 3 | B10: Estar | C10: 0.05 | E10: =SUM(F10:AG10) -> 0
A11: 4 | B11: Baño dormi 1 | C11: 0.05 | E11: =SUM(F11:AG11) -> 0
A12: 5 | B12: Baño dormi 2 | C12: 0.05 | E12: =SUM(F12:AG12) -> 0
A14: 2 | B14: CLOACALES | C14: =SUM(C15:C19) -> 0.3 | D14: =C14*C3 -> 1863000
A15: 1 | B15: 2/4 ambs | C15: 0.1 | E15: =SUM(F15:AG15) -> 0.1 | G15: 0.1
A16: 2 | B16: Acceso duplex | C16: 0.05 | E16: =SUM(F16:AG16) -> 0.05 | G16: 0.025 | H16: 0.02 | I16: 0.005
A17: 3 | B17: Estar | C17: 0.05 | E17: =SUM(F17:AG17) -> 0.05 | G17: 0.025 | H17: 0.02 | I17: 0.005
A18: 4 | B18: Dormi 1 | C18: 0.05 | E18: =SUM(F18:AG18) -> 0.05 | G18: 0.025 | H18: 0.02 | I18: 0.005
A19: 5 | B19: Dormi 2 | C19: 0.05 | E19: =SUM(F19:AG19) -> 0.05 | G19: 0.025 | H19: 0.02 | I19: 0.005
A21: 3 | B21: PLUVIALES | C21: =SUM(C22:C26) -> 0.1 | D21: =C21*C3 -> 621000
A22: 1 | B22: 2/4 ambs | C22: 0.02 | E22: =SUM(F22:AG22) -> 0.02 | G22: 0.015 | I22: 0.005
A23: 2 | B23: Acceso duplex | C23: 0.02 | E23: =SUM(F23:AG23) -> 0.02 | G23: 0.015 | I23: 0.005
A24: 3 | B24: Estar | C24: 0.02 | E24: =SUM(F24:AG24) -> 0.02 | G24: 0.015 | I24: 0.005
A25: 4 | B25: Dormi 1 | C25: 0.02 | E25: =SUM(F25:AG25) -> 0.02 | G25: 0.015 | I25: 0.005
A26: 5 | B26: Dormi 2 | C26: 0.02 | E26: =SUM(F26:AG26) -> 0.02 | G26: 0.015 | I26: 0.005
A28: 4 | B28: COLOCACIÓN | C28: =SUM(C29:C33) -> 0.1 | D28: =C28*C3 -> 621000
A29: 1 | B29: 2/4 ambs | C29: 0.02 | E29: =SUM(F29:AG29) -> 0
A30: 2 | B30: Acceso duplex | C30: 0.02 | E30: =SUM(F30:AG30) -> 0
A31: 3 | B31: Estar | C31: 0.02 | E31: =SUM(F31:AG31) -> 0
A32: 4 | B32: Dormi 1 | C32: 0.02 | E32: =SUM(F32:AG32) -> 0
A33: 5 | B33: Dormi 2 | C33: 0.02 | E33: =SUM(F33:AG33) -> 0
A35: 5 | B35: GAS | C35: =SUM(C36) -> 0.08 | D35: =C35*C3 -> 496800
A36: 1 | B36: General | C36: 0.08 | E36: =SUM(F36:AG36) -> 0
A38: 6 | B38: CALEFACCIÓN | C38: =SUM(C39:C43) -> 0.1 | D38: =C38*C3 -> 621000
A39: 1 | B39: 2/4 ambs | C39: 0.02 | E39: =SUM(F39:AG39) -> 0
A40: 2 | B40: Acceso duplex | C40: 0.02 | E40: =SUM(F40:AG40) -> 0
A41: 3 | B41: Estar | C41: 0.02 | E41: =SUM(F41:AG41) -> 0
A42: 4 | B42: Dormi 1 | C42: 0.02 | E42: =SUM(F42:AG42) -> 0
A43: 5 | B43: Dormi 2 | C43: 0.02 | E43: =SUM(F43:AG43) -> 0
A45: 7 | B45: ESPECIALES | C45: =SUM(C46:C49) -> 0.07 | D45: =C45*C3 -> 434700
A46: 1 | B46: Bacha parrilla | C46: 0.02 | E46: =SUM(F46:AG46) -> 0
...

Sheet M11
B1: SF - PLOMERÍA RODRIGO M11
A2: MES BASE ACTUALIZACIÓN | C2: 46113
A3: MONTO DE OBRA INICIAL | C3: =RESUMEN!D10 -> 6210000
A4: ANTICIPO | D4: =C4/C3 -> 0
F5: MAYO | H5: JUNIO | J5: JULIO | L5: AGOSTO | N5: SEPTIEMBRE | P5: OCTUBRE | R5: NOVIEMBRE | T5: DICIEMBRE | V5: ENERO | X5: FEBRERO | Z5: MARZO | AB5: ABRIL | AD5: MAYO | AF5: JUNIO
A6: ITEM | B6: DESCRIPCIÓN | C6: % ITEM | D6: MONTO TOTAL | E6: FINALIZADO | F6: C1 | H6: C2 | J6: C3 | L6: C4 | N6: C5 | P6: C6 | R6: C7 | T6: C8 | V6: C9 | X6: C10 | Z6: C11 | AB6: C12 | AD6: C13 | AF6: C14
A7: 1 | B7: AGUA | C7: =SUM(C8:C12) -> 0.25 | D7: =C7*C3 -> 1552500 | F7: Q1 | G7: Q2 | H7: Q1 | I7: Q2 | J7: Q1 | K7: Q2 | L7: Q1 | M7: Q2 | N7: Q1 | O7: Q2 | P7: Q1 | Q7: Q2 | R7: Q1 | S7: Q2 | T7: Q1 | U7: Q2 | V7: Q1 | W7: Q2 | X7: Q1 | Y7: Q2 | Z7: Q3 | AA7: Q4 | AB7: Q5 | AC7: Q6 | AD7: Q7 | AE7: Q8 | AF7: Q9 | AG7: Q10
A8: 1 | B8: 2/4 ambs | C8: 0.05 | E8: =SUM(F8:AG8) -> 0
A9: 2 | B9: Acceso duplex | C9: 0.05 | E9: =SUM(F9:AG9) -> 0
A10: 3 | B10: Estar | C10: 0.05 | E10: =SUM(F10:AG10) -> 0
A11: 4 | B11: Baño dormi 1 | C11: 0.05 | E11: =SUM(F11:AG11) -> 0
A12: 5 | B12: Baño dormi 2 | C12: 0.05 | E12: =SUM(F12:AG12) -> 0
A14: 2 | B14: CLOACALES | C14: =SUM(C15:C19) -> 0.3 | D14: =C14*C3 -> 1863000
A15: 1 | B15: 2/4 ambs | C15: 0.1 | E15: =SUM(F15:AG15) -> 0.1 | G15: 0.1
A16: 2 | B16: Acceso duplex | C16: 0.05 | E16: =SUM(F16:AG16) -> 0.05 | G16: 0.05
A17: 3 | B17: Estar | C17: 0.05 | E17: =SUM(F17:AG17) -> 0.05 | G17: 0.05
A18: 4 | B18: Dormi 1 | C18: 0.05 | E18: =SUM(F18:AG18) -> 0.05 | G18: 0.05
A19: 5 | B19: Dormi 2 | C19: 0.05 | E19: =SUM(F19:AG19) -> 0.05 | G19: 0.05
A21: 3 | B21: PLUVIALES | C21: =SUM(C22:C26) -> 0.1 | D21: =C21*C3 -> 621000
A22: 1 | B22: 2/4 ambs | C22: 0.02 | E22: =SUM(F22:AG22) -> 0.02 | G22: 0.01 | H22: 0.005 | I22: 0.005
A23: 2 | B23: Acceso duplex | C23: 0.02 | E23: =SUM(F23:AG23) -> 0.02 | G23: 0.01 | H23: 0.005 | I23: 0.005
A24: 3 | B24: Estar | C24: 0.02 | E24: =SUM(F24:AG24) -> 0.02 | G24: 0.01 | H24: 0.005 | I24: 0.005
A25: 4 | B25: Dormi 1 | C25: 0.02 | E25: =SUM(F25:AG25) -> 0.02 | G25: 0.01 | H25: 0.005 | I25: 0.005
A26: 5 | B26: Dormi 2 | C26: 0.02 | E26: =SUM(F26:AG26) -> 0.02 | G26: 0.01 | H26: 0.005 | I26: 0.005
A28: 4 | B28: COLOCACIÓN | C28: =SUM(C29:C33) -> 0.1 | D28: =C28*C3 -> 621000
A29: 1 | B29: 2/4 ambs | C29: 0.02 | E29: =SUM(F29:AG29) -> 0
A30: 2 | B30: Acceso duplex | C30: 0.02 | E30: =SUM(F30:AG30) -> 0
A31: 3 | B31: Estar | C31: 0.02 | E31: =SUM(F31:AG31) -> 0
A32: 4 | B32: Dormi 1 | C32: 0.02 | E32: =SUM(F32:AG32) -> 0
A33: 5 | B33: Dormi 2 | C33: 0.02 | E33: =SUM(F33:AG33) -> 0
A35: 5 | B35: GAS | C35: =SUM(C36) -> 0.08 | D35: =C35*C3 -> 496800
A36: 1 | B36: General | C36: 0.08 | E36: =SUM(F36:AG36) -> 0
A38: 6 | B38: CALEFACCIÓN | C38: =SUM(C39:C43) -> 0.1 | D38: =C38*C3 -> 621000
A39: 1 | B39: 2/4 ambs | C39: 0.02 | E39: =SUM(F39:AG39) -> 0
A40: 2 | B40: Acceso duplex | C40: 0.02 | E40: =SUM(F40:AG40) -> 0
A41: 3 | B41: Estar | C41: 0.02 | E41: =SUM(F41:AG41) -> 0
A42: 4 | B42: Dormi 1 | C42: 0.02 | E42: =SUM(F42:AG42) -> 0
A43: 5 | B43: Dormi 2 | C43: 0.02 | E43: =SUM(F43:AG43) -> 0
A45: 7 | B45: ESPECIALES | C45: =SUM(C46:C49) -> 0.07 | D45: =C45*C3 -> 434700
A46: 1 | B46: Bacha parrilla | C46: 0.02 | E46: =SUM(F46:AG46) -> 0
...

Sheet M10
B1: SF - PLOMERÍA RODRIGO M10
A2: MES BASE ACTUALIZACIÓN | C2: 46113
A3: MONTO DE OBRA INICIAL | C3: =RESUMEN!D10 -> 6210000
A4: ANTICIPO | D4: =C4/C3 -> 0
F5: MAYO | H5: JUNIO | J5: JULIO | L5: AGOSTO | N5: SEPTIEMBRE | P5: OCTUBRE | R5: NOVIEMBRE | T5: DICIEMBRE | V5: ENERO | X5: FEBRERO | Z5: MARZO | AB5: ABRIL | AD5: MAYO | AF5: JUNIO
A6: ITEM | B6: DESCRIPCIÓN | C6: % ITEM | D6: MONTO TOTAL | E6: FINALIZADO | F6: C1 | H6: C2 | J6: C3 | L6: C4 | N6: C5 | P6: C6 | R6: C7 | T6: C8 | V6: C9 | X6: C10 | Z6: C11 | AB6: C12 | AD6: C13 | AF6: C14
A7: 1 | B7: AGUA | C7: =SUM(C8:C12) -> 0.25 | D7: =C7*C3 -> 1552500 | F7: Q1 | G7: Q2 | H7: Q1 | I7: Q2 | J7: Q1 | K7: Q2 | L7: Q1 | M7: Q2 | N7: Q1 | O7: Q2 | P7: Q1 | Q7: Q2 | R7: Q1 | S7: Q2 | T7: Q1 | U7: Q2 | V7: Q1 | W7: Q2 | X7: Q1 | Y7: Q2 | Z7: Q3 | AA7: Q4 | AB7: Q5 | AC7: Q6 | AD7: Q7 | AE7: Q8 | AF7: Q9 | AG7: Q10
A8: 1 | B8: 2/4 ambs | C8: 0.05 | E8: =SUM(F8:AG8) -> 0
A9: 2 | B9: Acceso duplex | C9: 0.05 | E9: =SUM(F9:AG9) -> 0
A10: 3 | B10: Estar | C10: 0.05 | E10: =SUM(F10:AG10) -> 0
A11: 4 | B11: Baño dormi 1 | C11: 0.05 | E11: =SUM(F11:AG11) -> 0
A12: 5 | B12: Baño dormi 2 | C12: 0.05 | E12: =SUM(F12:AG12) -> 0
A14: 2 | B14: CLOACALES | C14: =SUM(C15:C19) -> 0.3 | D14: =C14*C3 -> 1863000
A15: 1 | B15: 2/4 ambs | C15: 0.1 | E15: =SUM(F15:AG15) -> 0.1 | G15: 0.1
A16: 2 | B16: Acceso duplex | C16: 0.05 | E16: =SUM(F16:AG16) -> 0.05 | G16: 0.05
A17: 3 | B17: Estar | C17: 0.05 | E17: =SUM(F17:AG17) -> 0.05 | G17: 0.05
A18: 4 | B18: Dormi 1 | C18: 0.05 | E18: =SUM(F18:AG18) -> 0.05 | G18: 0.05
A19: 5 | B19: Dormi 2 | C19: 0.05 | E19: =SUM(F19:AG19) -> 0.05 | G19: 0.05
A21: 3 | B21: PLUVIALES | C21: =SUM(C22:C26) -> 0.1 | D21: =C21*C3 -> 621000
A22: 1 | B22: 2/4 ambs | C22: 0.02 | E22: =SUM(F22:AG22) -> 0.02 | G22: 0.015 | I22: 0.005
A23: 2 | B23: Acceso duplex | C23: 0.02 | E23: =SUM(F23:AG23) -> 0.02 | G23: 0.015 | I23: 0.005
A24: 3 | B24: Estar | C24: 0.02 | E24: =SUM(F24:AG24) -> 0.02 | G24: 0.015 | I24: 0.005
A25: 4 | B25: Dormi 1 | C25: 0.02 | E25: =SUM(F25:AG25) -> 0.02 | G25: 0.015 | I25: 0.005
A26: 5 | B26: Dormi 2 | C26: 0.02 | E26: =SUM(F26:AG26) -> 0.02 | G26: 0.015 | I26: 0.005
A28: 4 | B28: COLOCACIÓN | C28: =SUM(C29:C33) -> 0.1 | D28: =C28*C3 -> 621000
A29: 1 | B29: 2/4 ambs | C29: 0.02 | E29: =SUM(F29:AG29) -> 0
A30: 2 | B30: Acceso duplex | C30: 0.02 | E30: =SUM(F30:AG30) -> 0
A31: 3 | B31: Estar | C31: 0.02 | E31: =SUM(F31:AG31) -> 0
A32: 4 | B32: Dormi 1 | C32: 0.02 | E32: =SUM(F32:AG32) -> 0
A33: 5 | B33: Dormi 2 | C33: 0.02 | E33: =SUM(F33:AG33) -> 0
A35: 5 | B35: GAS | C35: =SUM(C36) -> 0.08 | D35: =C35*C3 -> 496800
A36: 1 | B36: General | C36: 0.08 | E36: =SUM(F36:AG36) -> 0
A38: 6 | B38: CALEFACCIÓN | C38: =SUM(C39:C43) -> 0.1 | D38: =C38*C3 -> 621000
A39: 1 | B39: 2/4 ambs | C39: 0.02 | E39: =SUM(F39:AG39) -> 0
A40: 2 | B40: Acceso duplex | C40: 0.02 | E40: =SUM(F40:AG40) -> 0
A41: 3 | B41: Estar | C41: 0.02 | E41: =SUM(F41:AG41) -> 0
A42: 4 | B42: Dormi 1 | C42: 0.02 | E42: =SUM(F42:AG42) -> 0
A43: 5 | B43: Dormi 2 | C43: 0.02 | E43: =SUM(F43:AG43) -> 0
A45: 7 | B45: ESPECIALES | C45: =SUM(C46:C49) -> 0.07 | D45: =C45*C3 -> 434700
A46: 1 | B46: Bacha parrilla | C46: 0.02 | E46: =SUM(F46:AG46) -> 0
...

Sheet M09
B1: SF - PLOMERÍA RODRIGO M09
A2: MES BASE ACTUALIZACIÓN | C2: 46113
A3: MONTO DE OBRA INICIAL | C3: =RESUMEN!D10 -> 6210000
A4: ANTICIPO | D4: =C4/C3 -> 0
F5: MAYO | H5: JUNIO | J5: JULIO | L5: AGOSTO | N5: SEPTIEMBRE | P5: OCTUBRE | R5: NOVIEMBRE | T5: DICIEMBRE | V5: ENERO | X5: FEBRERO | Z5: MARZO | AB5: ABRIL | AD5: MAYO | AF5: JUNIO
A6: ITEM | B6: DESCRIPCIÓN | C6: % ITEM | D6: MONTO TOTAL | E6: FINALIZADO | F6: C1 | H6: C2 | J6: C3 | L6: C4 | N6: C5 | P6: C6 | R6: C7 | T6: C8 | V6: C9 | X6: C10 | Z6: C11 | AB6: C12 | AD6: C13 | AF6: C14
A7: 1 | B7: AGUA | C7: =SUM(C8:C12) -> 0.25 | D7: =C7*C3 -> 1552500 | F7: Q1 | G7: Q2 | H7: Q1 | I7: Q2 | J7: Q1 | K7: Q2 | L7: Q1 | M7: Q2 | N7: Q1 | O7: Q2 | P7: Q1 | Q7: Q2 | R7: Q1 | S7: Q2 | T7: Q1 | U7: Q2 | V7: Q1 | W7: Q2 | X7: Q1 | Y7: Q2 | Z7: Q3 | AA7: Q4 | AB7: Q5 | AC7: Q6 | AD7: Q7 | AE7: Q8 | AF7: Q9 | AG7: Q10
A8: 1 | B8: 2/4 ambs | C8: 0.05 | E8: =SUM(F8:AG8) -> 0
A9: 2 | B9: Acceso duplex | C9: 0.05 | E9: =SUM(F9:AG9) -> 0
A10: 3 | B10: Estar | C10: 0.05 | E10: =SUM(F10:AG10) -> 0
A11: 4 | B11: Baño dormi 1 | C11: 0.05 | E11: =SUM(F11:AG11) -> 0
A12: 5 | B12: Baño dormi 2 | C12: 0.05 | E12: =SUM(F12:AG12) -> 0
A14: 2 | B14: CLOACALES | C14: =SUM(C15:C19) -> 0.3 | D14: =C14*C3 -> 1863000
A15: 1 | B15: 2/4 ambs | C15: 0.1 | E15: =SUM(F15:AG15) -> 0
A16: 2 | B16: Acceso duplex | C16: 0.05 | E16: =SUM(F16:AG16) -> 0
A17: 3 | B17: Estar | C17: 0.05 | E17: =SUM(F17:AG17) -> 0
A18: 4 | B18: Dormi 1 | C18: 0.05 | E18: =SUM(F18:AG18) -> 0
A19: 5 | B19: Dormi 2 | C19: 0.05 | E19: =SUM(F19:AG19) -> 0
A21: 3 | B21: PLUVIALES | C21: =SUM(C22:C26) -> 0.1 | D21: =C21*C3 -> 621000
A22: 1 | B22: 2/4 ambs | C22: 0.02 | E22: =SUM(F22:AG22) -> 0
A23: 2 | B23: Acceso duplex | C23: 0.02 | E23: =SUM(F23:AG23) -> 0
A24: 3 | B24: Estar | C24: 0.02 | E24: =SUM(F24:AG24) -> 0
A25: 4 | B25: Dormi 1 | C25: 0.02 | E25: =SUM(F25:AG25) -> 0
A26: 5 | B26: Dormi 2 | C26: 0.02 | E26: =SUM(F26:AG26) -> 0
A28: 4 | B28: COLOCACIÓN | C28: =SUM(C29:C33) -> 0.1 | D28: =C28*C3 -> 621000
A29: 1 | B29: 2/4 ambs | C29: 0.02 | E29: =SUM(F29:AG29) -> 0
A30: 2 | B30: Acceso duplex | C30: 0.02 | E30: =SUM(F30:AG30) -> 0
A31: 3 | B31: Estar | C31: 0.02 | E31: =SUM(F31:AG31) -> 0
A32: 4 | B32: Dormi 1 | C32: 0.02 | E32: =SUM(F32:AG32) -> 0
A33: 5 | B33: Dormi 2 | C33: 0.02 | E33: =SUM(F33:AG33) -> 0
A35: 5 | B35: GAS | C35: =SUM(C36) -> 0.08 | D35: =C35*C3 -> 496800
A36: 1 | B36: General | C36: 0.08 | E36: =SUM(F36:AG36) -> 0
A38: 6 | B38: CALEFACCIÓN | C38: =SUM(C39:C43) -> 0.1 | D38: =C38*C3 -> 621000
A39: 1 | B39: 2/4 ambs | C39: 0.02 | E39: =SUM(F39:AG39) -> 0
A40: 2 | B40: Acceso duplex | C40: 0.02 | E40: =SUM(F40:AG40) -> 0
A41: 3 | B41: Estar | C41: 0.02 | E41: =SUM(F41:AG41) -> 0
A42: 4 | B42: Dormi 1 | C42: 0.02 | E42: =SUM(F42:AG42) -> 0
A43: 5 | B43: Dormi 2 | C43: 0.02 | E43: =SUM(F43:AG43) -> 0
A45: 7 | B45: ESPECIALES | C45: =SUM(C46:C49) -> 0.07 | D45: =C45*C3 -> 434700
A46: 1 | B46: Bacha parrilla | C46: 0.02 | E46: =SUM(F46:AG46) -> 0
...

Sheet M08
B1: SF - PLOMERÍA RODRIGO M08
A2: MES BASE ACTUALIZACIÓN | C2: 46113
A3: MONTO DE OBRA INICIAL | C3: =RESUMEN!D10 -> 6210000
A4: ANTICIPO | D4: =C4/C3 -> 0
F5: AGOSTO | H5: SEPTIEMBRE | J5: OCTUBRE | L5: NOVIEMBRE | N5: DICIEMBRE | P5: ENERO | R5: FEBRERO | T5: MARZO | V5: ABRIL | X5: MAYO | Z5: JUNIO | AB5: JULIO | AD5: AGOSTO | AF5: SEPTIEMBRE
A6: ITEM | B6: DESCRIPCIÓN | C6: % ITEM | D6: MONTO TOTAL | E6: FINALIZADO | F6: C1 | H6: C2 | J6: C3 | L6: C4 | N6: C5 | P6: C6 | R6: C7 | T6: C8 | V6: C9 | X6: C10 | Z6: C11 | AB6: C12 | AD6: C13 | AF6: C14
A7: 1 | B7: AGUA | C7: =SUM(C8:C12) -> 0.25 | D7: =C7*C3 -> 1552500 | F7: Q1 | G7: Q2 | H7: Q1 | I7: Q2 | J7: Q1 | K7: Q2 | L7: Q1 | M7: Q2 | N7: Q1 | O7: Q2 | P7: Q1 | Q7: Q2 | R7: Q1 | S7: Q2 | T7: Q1 | U7: Q2 | V7: Q1 | W7: Q2 | X7: Q1 | Y7: Q2 | Z7: Q3 | AA7: Q4 | AB7: Q5 | AC7: Q6 | AD7: Q7 | AE7: Q8 | AF7: Q9 | AG7: Q10
A8: 1 | B8: 2/4 ambs | C8: 0.05 | E8: =SUM(F8:AG8) -> 0
A9: 2 | B9: Acceso duplex | C9: 0.05 | E9: =SUM(F9:AG9) -> 0
A10: 3 | B10: Estar | C10: 0.05 | E10: =SUM(F10:AG10) -> 0
A11: 4 | B11: Baño dormi 1 | C11: 0.05 | E11: =SUM(F11:AG11) -> 0
A12: 5 | B12: Baño dormi 2 | C12: 0.05 | E12: =SUM(F12:AG12) -> 0
A14: 2 | B14: CLOACALES | C14: =SUM(C15:C19) -> 0.3 | D14: =C14*C3 -> 1863000
A15: 1 | B15: 2/4 ambs | C15: 0.1 | E15: =SUM(F15:AG15) -> 0
A16: 2 | B16: Acceso duplex | C16: 0.05 | E16: =SUM(F16:AG16) -> 0
A17: 3 | B17: Estar | C17: 0.05 | E17: =SUM(F17:AG17) -> 0
A18: 4 | B18: Dormi 1 | C18: 0.05 | E18: =SUM(F18:AG18) -> 0
A19: 5 | B19: Dormi 2 | C19: 0.05 | E19: =SUM(F19:AG19) -> 0
A21: 3 | B21: PLUVIALES | C21: =SUM(C22:C26) -> 0.1 | D21: =C21*C3 -> 621000
A22: 1 | B22: 2/4 ambs | C22: 0.02 | E22: =SUM(F22:AG22) -> 0
A23: 2 | B23: Acceso duplex | C23: 0.02 | E23: =SUM(F23:AG23) -> 0
A24: 3 | B24: Estar | C24: 0.02 | E24: =SUM(F24:AG24) -> 0
A25: 4 | B25: Dormi 1 | C25: 0.02 | E25: =SUM(F25:AG25) -> 0
A26: 5 | B26: Dormi 2 | C26: 0.02 | E26: =SUM(F26:AG26) -> 0
A28: 4 | B28: COLOCACIÓN | C28: =SUM(C29:C33) -> 0.1 | D28: =C28*C3 -> 621000
A29: 1 | B29: 2/4 ambs | C29: 0.02 | E29: =SUM(F29:AG29) -> 0
A30: 2 | B30: Acceso duplex | C30: 0.02 | E30: =SUM(F30:AG30) -> 0
A31: 3 | B31: Estar | C31: 0.02 | E31: =SUM(F31:AG31) -> 0
A32: 4 | B32: Dormi 1 | C32: 0.02 | E32: =SUM(F32:AG32) -> 0
A33: 5 | B33: Dormi 2 | C33: 0.02 | E33: =SUM(F33:AG33) -> 0
A35: 5 | B35: GAS | C35: =SUM(C36) -> 0.08 | D35: =C35*C3 -> 496800
A36: 1 | B36: General | C36: 0.08 | E36: =SUM(F36:AG36) -> 0
A38: 6 | B38: CALEFACCIÓN | C38: =SUM(C39:C43) -> 0.1 | D38: =C38*C3 -> 621000
A39: 1 | B39: 2/4 ambs | C39: 0.02 | E39: =SUM(F39:AG39) -> 0
A40: 2 | B40: Acceso duplex | C40: 0.02 | E40: =SUM(F40:AG40) -> 0
A41: 3 | B41: Estar | C41: 0.02 | E41: =SUM(F41:AG41) -> 0
A42: 4 | B42: Dormi 1 | C42: 0.02 | E42: =SUM(F42:AG42) -> 0
A43: 5 | B43: Dormi 2 | C43: 0.02 | E43: =SUM(F43:AG43) -> 0
A45: 7 | B45: ESPECIALES | C45: =SUM(C46:C49) -> 0.07 | D45: =C45*C3 -> 434700
A46: 1 | B46: Bacha parrilla | C46: 0.02 | E46: =SUM(F46:AG46) -> 0
...

Sheet M07
B1: SF - PLOMERÍA RODRIGO M07
A2: MES BASE ACTUALIZACIÓN | C2: 46113
A3: MONTO DE OBRA INICIAL | C3: =RESUMEN!D11 -> 9056250
A4: ANTICIPO | D4: =C4/C3 -> 0
F5: AGOSTO | H5: SEPTIEMBRE | J5: OCTUBRE | L5: NOVIEMBRE | N5: DICIEMBRE | P5: ENERO | R5: FEBRERO | T5: MARZO | V5: ABRIL | X5: MAYO | Z5: JUNIO | AB5: JULIO | AD5: AGOSTO | AF5: SEPTIEMBRE
A6: ITEM | B6: DESCRIPCIÓN | C6: % ITEM | D6: MONTO TOTAL | E6: FINALIZADO | F6: C1 | H6: C2 | J6: C3 | L6: C4 | N6: C5 | P6: C6 | R6: C7 | T6: C8 | V6: C9 | X6: C10 | Z6: C11 | AB6: C12 | AD6: C13 | AF6: C14
A7: 1 | B7: AGUA | C7: =SUM(C8:C12) -> 0.25 | D7: =C7*C3 -> 2264062.5 | F7: Q1 | G7: Q2 | H7: Q1 | I7: Q2 | J7: Q1 | K7: Q2 | L7: Q1 | M7: Q2 | N7: Q1 | O7: Q2 | P7: Q1 | Q7: Q2 | R7: Q1 | S7: Q2 | T7: Q1 | U7: Q2 | V7: Q1 | W7: Q2 | X7: Q1 | Y7: Q2 | Z7: Q3 | AA7: Q4 | AB7: Q5 | AC7: Q6 | AD7: Q7 | AE7: Q8 | AF7: Q9 | AG7: Q10
A8: 1 | B8: 2/4 ambs | C8: 0.05 | E8: =SUM(F8:AG8) -> 0
A9: 2 | B9: Acceso duplex | C9: 0.05 | E9: =SUM(F9:AG9) -> 0
A10: 3 | B10: Estar | C10: 0.05 | E10: =SUM(F10:AG10) -> 0
A11: 4 | B11: Baño dormi 1 | C11: 0.05 | E11: =SUM(F11:AG11) -> 0
A12: 5 | B12: Baño dormi 2 | C12: 0.05 | E12: =SUM(F12:AG12) -> 0
A14: 2 | B14: CLOACALES | C14: =SUM(C15:C19) -> 0.3 | D14: =C14*C3 -> 2716875
A15: 1 | B15: 2/4 ambs | C15: 0.1 | E15: =SUM(F15:AG15) -> 0
A16: 2 | B16: Acceso duplex | C16: 0.05 | E16: =SUM(F16:AG16) -> 0
A17: 3 | B17: Estar | C17: 0.05 | E17: =SUM(F17:AG17) -> 0
A18: 4 | B18: Dormi 1 | C18: 0.05 | E18: =SUM(F18:AG18) -> 0
A19: 5 | B19: Dormi 2 | C19: 0.05 | E19: =SUM(F19:AG19) -> 0
A21: 3 | B21: PLUVIALES | C21: =SUM(C22:C26) -> 0.1 | D21: =C21*C3 -> 905625
A22: 1 | B22: 2/4 ambs | C22: 0.02 | E22: =SUM(F22:AG22) -> 0
A23: 2 | B23: Acceso duplex | C23: 0.02 | E23: =SUM(F23:AG23) -> 0
A24: 3 | B24: Estar | C24: 0.02 | E24: =SUM(F24:AG24) -> 0
A25: 4 | B25: Dormi 1 | C25: 0.02 | E25: =SUM(F25:AG25) -> 0
A26: 5 | B26: Dormi 2 | C26: 0.02 | E26: =SUM(F26:AG26) -> 0
A28: 4 | B28: COLOCACIÓN | C28: =SUM(C29:C33) -> 0.1 | D28: =C28*C3 -> 905625
A29: 1 | B29: 2/4 ambs | C29: 0.02 | E29: =SUM(F29:AG29) -> 0
A30: 2 | B30: Acceso duplex | C30: 0.02 | E30: =SUM(F30:AG30) -> 0
A31: 3 | B31: Estar | C31: 0.02 | E31: =SUM(F31:AG31) -> 0
A32: 4 | B32: Dormi 1 | C32: 0.02 | E32: =SUM(F32:AG32) -> 0
A33: 5 | B33: Dormi 2 | C33: 0.02 | E33: =SUM(F33:AG33) -> 0
A35: 5 | B35: GAS | C35: =SUM(C36) -> 0.08 | D35: =C35*C3 -> 724500
A36: 1 | B36: General | C36: 0.08 | E36: =SUM(F36:AG36) -> 0
A38: 6 | B38: CALEFACCIÓN | C38: =SUM(C39:C43) -> 0.1 | D38: =C38*C3 -> 905625
A39: 1 | B39: 2/4 ambs | C39: 0.02 | E39: =SUM(F39:AG39) -> 0
A40: 2 | B40: Acceso duplex | C40: 0.02 | E40: =SUM(F40:AG40) -> 0
A41: 3 | B41: Estar | C41: 0.02 | E41: =SUM(F41:AG41) -> 0
A42: 4 | B42: Dormi 1 | C42: 0.02 | E42: =SUM(F42:AG42) -> 0
A43: 5 | B43: Dormi 2 | C43: 0.02 | E43: =SUM(F43:AG43) -> 0
A45: 7 | B45: ESPECIALES | C45: =SUM(C46:C49) -> 0.07 | D45: =C45*C3 -> 633937.5
A46: 1 | B46: Bacha parrilla | C46: 0.02 | E46: =SUM(F46:AG46) -> 0
...

Sheet M06
B1: SF - PLOMERÍA RODRIGO M06
A2: MES BASE ACTUALIZACIÓN | C2: 46113
A3: MONTO DE OBRA INICIAL | C3: =RESUMEN!D11 -> 9056250
A4: ANTICIPO | D4: =C4/C3 -> 0
F5: AGOSTO | H5: SEPTIEMBRE | J5: OCTUBRE | L5: NOVIEMBRE | N5: DICIEMBRE | P5: ENERO | R5: FEBRERO | T5: MARZO | V5: ABRIL | X5: MAYO | Z5: JUNIO | AB5: JULIO | AD5: AGOSTO | AF5: SEPTIEMBRE
A6: ITEM | B6: DESCRIPCIÓN | C6: % ITEM | D6: MONTO TOTAL | E6: FINALIZADO | F6: C1 | H6: C2 | J6: C3 | L6: C4 | N6: C5 | P6: C6 | R6: C7 | T6: C8 | V6: C9 | X6: C10 | Z6: C11 | AB6: C12 | AD6: C13 | AF6: C14
A7: 1 | B7: AGUA | C7: =SUM(C8:C12) -> 0.25 | D7: =C7*C3 -> 2264062.5 | F7: Q1 | G7: Q2 | H7: Q1 | I7: Q2 | J7: Q1 | K7: Q2 | L7: Q1 | M7: Q2 | N7: Q1 | O7: Q2 | P7: Q1 | Q7: Q2 | R7: Q1 | S7: Q2 | T7: Q1 | U7: Q2 | V7: Q1 | W7: Q2 | X7: Q1 | Y7: Q2 | Z7: Q3 | AA7: Q4 | AB7: Q5 | AC7: Q6 | AD7: Q7 | AE7: Q8 | AF7: Q9 | AG7: Q10
A8: 1 | B8: 2/4 ambs | C8: 0.05 | E8: =SUM(F8:AG8) -> 0
A9: 2 | B9: Acceso duplex | C9: 0.05 | E9: =SUM(F9:AG9) -> 0
A10: 3 | B10: Estar | C10: 0.05 | E10: =SUM(F10:AG10) -> 0
A11: 4 | B11: Baño dormi 1 | C11: 0.05 | E11: =SUM(F11:AG11) -> 0
A12: 5 | B12: Baño dormi 2 | C12: 0.05 | E12: =SUM(F12:AG12) -> 0
A14: 2 | B14: CLOACALES | C14: =SUM(C15:C19) -> 0.3 | D14: =C14*C3 -> 2716875
A15: 1 | B15: 2/4 ambs | C15: 0.1 | E15: =SUM(F15:AG15) -> 0
A16: 2 | B16: Acceso duplex | C16: 0.05 | E16: =SUM(F16:AG16) -> 0
A17: 3 | B17: Estar | C17: 0.05 | E17: =SUM(F17:AG17) -> 0
A18: 4 | B18: Dormi 1 | C18: 0.05 | E18: =SUM(F18:AG18) -> 0
A19: 5 | B19: Dormi 2 | C19: 0.05 | E19: =SUM(F19:AG19) -> 0
A21: 3 | B21: PLUVIALES | C21: =SUM(C22:C26) -> 0.1 | D21: =C21*C3 -> 905625
A22: 1 | B22: 2/4 ambs | C22: 0.02 | E22: =SUM(F22:AG22) -> 0
A23: 2 | B23: Acceso duplex | C23: 0.02 | E23: =SUM(F23:AG23) -> 0
A24: 3 | B24: Estar | C24: 0.02 | E24: =SUM(F24:AG24) -> 0
A25: 4 | B25: Dormi 1 | C25: 0.02 | E25: =SUM(F25:AG25) -> 0
A26: 5 | B26: Dormi 2 | C26: 0.02 | E26: =SUM(F26:AG26) -> 0
A28: 4 | B28: COLOCACIÓN | C28: =SUM(C29:C33) -> 0.1 | D28: =C28*C3 -> 905625
A29: 1 | B29: 2/4 ambs | C29: 0.02 | E29: =SUM(F29:AG29) -> 0
A30: 2 | B30: Acceso duplex | C30: 0.02 | E30: =SUM(F30:AG30) -> 0
A31: 3 | B31: Estar | C31: 0.02 | E31: =SUM(F31:AG31) -> 0
A32: 4 | B32: Dormi 1 | C32: 0.02 | E32: =SUM(F32:AG32) -> 0
A33: 5 | B33: Dormi 2 | C33: 0.02 | E33: =SUM(F33:AG33) -> 0
A35: 5 | B35: GAS | C35: =SUM(C36) -> 0.08 | D35: =C35*C3 -> 724500
A36: 1 | B36: General | C36: 0.08 | E36: =SUM(F36:AG36) -> 0
A38: 6 | B38: CALEFACCIÓN | C38: =SUM(C39:C43) -> 0.1 | D38: =C38*C3 -> 905625
A39: 1 | B39: 2/4 ambs | C39: 0.02 | E39: =SUM(F39:AG39) -> 0
A40: 2 | B40: Acceso duplex | C40: 0.02 | E40: =SUM(F40:AG40) -> 0
A41: 3 | B41: Estar | C41: 0.02 | E41: =SUM(F41:AG41) -> 0
A42: 4 | B42: Dormi 1 | C42: 0.02 | E42: =SUM(F42:AG42) -> 0
A43: 5 | B43: Dormi 2 | C43: 0.02 | E43: =SUM(F43:AG43) -> 0
A45: 7 | B45: ESPECIALES | C45: =SUM(C46:C49) -> 0.07 | D45: =C45*C3 -> 633937.5
A46: 1 | B46: Bacha parrilla | C46: 0.02 | E46: =SUM(F46:AG46) -> 0
...

Sheet M05
B1: SF - PLOMERÍA RODRIGO M05
A2: MES BASE ACTUALIZACIÓN | C2: 46113
A3: MONTO DE OBRA INICIAL | C3: =RESUMEN!D11 -> 9056250
A4: ANTICIPO | D4: =C4/C3 -> 0
F5: AGOSTO | H5: SEPTIEMBRE | J5: OCTUBRE | L5: NOVIEMBRE | N5: DICIEMBRE | P5: ENERO | R5: FEBRERO | T5: MARZO | V5: ABRIL | X5: MAYO | Z5: JUNIO | AB5: JULIO | AD5: AGOSTO | AF5: SEPTIEMBRE
A6: ITEM | B6: DESCRIPCIÓN | C6: % ITEM | D6: MONTO TOTAL | E6: FINALIZADO | F6: C1 | H6: C2 | J6: C3 | L6: C4 | N6: C5 | P6: C6 | R6: C7 | T6: C8 | V6: C9 | X6: C10 | Z6: C11 | AB6: C12 | AD6: C13 | AF6: C14
A7: 1 | B7: AGUA | C7: =SUM(C8:C12) -> 0.25 | D7: =C7*C3 -> 2264062.5 | F7: Q1 | G7: Q2 | H7: Q1 | I7: Q2 | J7: Q1 | K7: Q2 | L7: Q1 | M7: Q2 | N7: Q1 | O7: Q2 | P7: Q1 | Q7: Q2 | R7: Q1 | S7: Q2 | T7: Q1 | U7: Q2 | V7: Q1 | W7: Q2 | X7: Q1 | Y7: Q2 | Z7: Q3 | AA7: Q4 | AB7: Q5 | AC7: Q6 | AD7: Q7 | AE7: Q8 | AF7: Q9 | AG7: Q10
A8: 1 | B8: 2/4 ambs | C8: 0.05 | E8: =SUM(F8:AG8) -> 0
A9: 2 | B9: Acceso duplex | C9: 0.05 | E9: =SUM(F9:AG9) -> 0
A10: 3 | B10: Estar | C10: 0.05 | E10: =SUM(F10:AG10) -> 0
A11: 4 | B11: Baño dormi 1 | C11: 0.05 | E11: =SUM(F11:AG11) -> 0
A12: 5 | B12: Baño dormi 2 | C12: 0.05 | E12: =SUM(F12:AG12) -> 0
A14: 2 | B14: CLOACALES | C14: =SUM(C15:C19) -> 0.3 | D14: =C14*C3 -> 2716875
A15: 1 | B15: 2/4 ambs | C15: 0.1 | E15: =SUM(F15:AG15) -> 0
A16: 2 | B16: Acceso duplex | C16: 0.05 | E16: =SUM(F16:AG16) -> 0
A17: 3 | B17: Estar | C17: 0.05 | E17: =SUM(F17:AG17) -> 0
A18: 4 | B18: Dormi 1 | C18: 0.05 | E18: =SUM(F18:AG18) -> 0
A19: 5 | B19: Dormi 2 | C19: 0.05 | E19: =SUM(F19:AG19) -> 0
A21: 3 | B21: PLUVIALES | C21: =SUM(C22:C26) -> 0.1 | D21: =C21*C3 -> 905625
A22: 1 | B22: 2/4 ambs | C22: 0.02 | E22: =SUM(F22:AG22) -> 0
A23: 2 | B23: Acceso duplex | C23: 0.02 | E23: =SUM(F23:AG23) -> 0
A24: 3 | B24: Estar | C24: 0.02 | E24: =SUM(F24:AG24) -> 0
A25: 4 | B25: Dormi 1 | C25: 0.02 | E25: =SUM(F25:AG25) -> 0
A26: 5 | B26: Dormi 2 | C26: 0.02 | E26: =SUM(F26:AG26) -> 0
A28: 4 | B28: COLOCACIÓN | C28: =SUM(C29:C33) -> 0.1 | D28: =C28*C3 -> 905625
A29: 1 | B29: 2/4 ambs | C29: 0.02 | E29: =SUM(F29:AG29) -> 0
A30: 2 | B30: Acceso duplex | C30: 0.02 | E30: =SUM(F30:AG30) -> 0
A31: 3 | B31: Estar | C31: 0.02 | E31: =SUM(F31:AG31) -> 0
A32: 4 | B32: Dormi 1 | C32: 0.02 | E32: =SUM(F32:AG32) -> 0
A33: 5 | B33: Dormi 2 | C33: 0.02 | E33: =SUM(F33:AG33) -> 0
A35: 5 | B35: GAS | C35: =SUM(C36) -> 0.08 | D35: =C35*C3 -> 724500
A36: 1 | B36: General | C36: 0.08 | E36: =SUM(F36:AG36) -> 0
A38: 6 | B38: CALEFACCIÓN | C38: =SUM(C39:C43) -> 0.1 | D38: =C38*C3 -> 905625
A39: 1 | B39: 2/4 ambs | C39: 0.02 | E39: =SUM(F39:AG39) -> 0
A40: 2 | B40: Acceso duplex | C40: 0.02 | E40: =SUM(F40:AG40) -> 0
A41: 3 | B41: Estar | C41: 0.02 | E41: =SUM(F41:AG41) -> 0
A42: 4 | B42: Dormi 1 | C42: 0.02 | E42: =SUM(F42:AG42) -> 0
A43: 5 | B43: Dormi 2 | C43: 0.02 | E43: =SUM(F43:AG43) -> 0
A45: 7 | B45: ESPECIALES | C45: =SUM(C46:C49) -> 0.07 | D45: =C45*C3 -> 633937.5
A46: 1 | B46: Bacha parrilla | C46: 0.02 | E46: =SUM(F46:AG46) -> 0
...

Sheet M13
B1: SF - PLOMERÍA RODRIGO M13
A2: MES BASE ACTUALIZACIÓN | C2: 46113
A3: MONTO DE OBRA INICIAL | C3: =RESUMEN!D11 -> 9056250
A4: ANTICIPO | D4: =C4/C3 -> 0
F5: NOVIEMBRE | H5: DICIEMBRE | J5: ENERO | L5: FEBRERO | N5: MARZO | P5: ABRIL | R5: MAYO | T5: JUNIO | V5: JULIO | X5: AGOSTO | Z5: SEPTIEMBRE | AB5: OCTUBRE | AD5: NOVIEMBRE | AF5: DICIEMBRE
A6: ITEM | B6: DESCRIPCIÓN | C6: % ITEM | D6: MONTO TOTAL | E6: FINALIZADO | F6: C1 | H6: C2 | J6: C3 | L6: C4 | N6: C5 | P6: C6 | R6: C7 | T6: C8 | V6: C9 | X6: C10 | Z6: C11 | AB6: C12 | AD6: C13 | AF6: C14
A7: 1 | B7: AGUA | C7: =SUM(C8:C12) -> 0.25 | D7: =C7*C3 -> 2264062.5 | F7: Q1 | G7: Q2 | H7: Q1 | I7: Q2 | J7: Q1 | K7: Q2 | L7: Q1 | M7: Q2 | N7: Q1 | O7: Q2 | P7: Q1 | Q7: Q2 | R7: Q1 | S7: Q2 | T7: Q1 | U7: Q2 | V7: Q1 | W7: Q2 | X7: Q1 | Y7: Q2 | Z7: Q3 | AA7: Q4 | AB7: Q5 | AC7: Q6 | AD7: Q7 | AE7: Q8 | AF7: Q9 | AG7: Q10
A8: 1 | B8: 2/4 ambs | C8: 0.05 | E8: =SUM(F8:AG8) -> 0
A9: 2 | B9: Acceso duplex | C9: 0.05 | E9: =SUM(F9:AG9) -> 0
A10: 3 | B10: Estar | C10: 0.05 | E10: =SUM(F10:AG10) -> 0
A11: 4 | B11: Baño dormi 1 | C11: 0.05 | E11: =SUM(F11:AG11) -> 0
A12: 5 | B12: Baño dormi 2 | C12: 0.05 | E12: =SUM(F12:AG12) -> 0
A14: 2 | B14: CLOACALES | C14: =SUM(C15:C19) -> 0.3 | D14: =C14*C3 -> 2716875
A15: 1 | B15: 2/4 ambs | C15: 0.1 | E15: =SUM(F15:AG15) -> 0
A16: 2 | B16: Acceso duplex | C16: 0.05 | E16: =SUM(F16:AG16) -> 0
A17: 3 | B17: Estar | C17: 0.05 | E17: =SUM(F17:AG17) -> 0
A18: 4 | B18: Dormi 1 | C18: 0.05 | E18: =SUM(F18:AG18) -> 0
A19: 5 | B19: Dormi 2 | C19: 0.05 | E19: =SUM(F19:AG19) -> 0
A21: 3 | B21: PLUVIALES | C21: =SUM(C22:C26) -> 0.1 | D21: =C21*C3 -> 905625
A22: 1 | B22: 2/4 ambs | C22: 0.02 | E22: =SUM(F22:AG22) -> 0
A23: 2 | B23: Acceso duplex | C23: 0.02 | E23: =SUM(F23:AG23) -> 0
A24: 3 | B24: Estar | C24: 0.02 | E24: =SUM(F24:AG24) -> 0
A25: 4 | B25: Dormi 1 | C25: 0.02 | E25: =SUM(F25:AG25) -> 0
A26: 5 | B26: Dormi 2 | C26: 0.02 | E26: =SUM(F26:AG26) -> 0
A28: 4 | B28: COLOCACIÓN | C28: =SUM(C29:C33) -> 0.1 | D28: =C28*C3 -> 905625
A29: 1 | B29: 2/4 ambs | C29: 0.02 | E29: =SUM(F29:AG29) -> 0
A30: 2 | B30: Acceso duplex | C30: 0.02 | E30: =SUM(F30:AG30) -> 0
A31: 3 | B31: Estar | C31: 0.02 | E31: =SUM(F31:AG31) -> 0
A32: 4 | B32: Dormi 1 | C32: 0.02 | E32: =SUM(F32:AG32) -> 0
A33: 5 | B33: Dormi 2 | C33: 0.02 | E33: =SUM(F33:AG33) -> 0
A35: 5 | B35: GAS | C35: =SUM(C36) -> 0.08 | D35: =C35*C3 -> 724500
A36: 1 | B36: General | C36: 0.08 | E36: =SUM(F36:AG36) -> 0
A38: 6 | B38: CALEFACCIÓN | C38: =SUM(C39:C43) -> 0.1 | D38: =C38*C3 -> 905625
A39: 1 | B39: 2/4 ambs | C39: 0.02 | E39: =SUM(F39:AG39) -> 0
A40: 2 | B40: Acceso duplex | C40: 0.02 | E40: =SUM(F40:AG40) -> 0
A41: 3 | B41: Estar | C41: 0.02 | E41: =SUM(F41:AG41) -> 0
A42: 4 | B42: Dormi 1 | C42: 0.02 | E42: =SUM(F42:AG42) -> 0
A43: 5 | B43: Dormi 2 | C43: 0.02 | E43: =SUM(F43:AG43) -> 0
A45: 7 | B45: ESPECIALES | C45: =SUM(C46:C49) -> 0.07 | D45: =C45*C3 -> 633937.5
A46: 1 | B46: Bacha parrilla | C46: 0.02 | E46: =SUM(F46:AG46) -> 0
...

Sheet M04
B1: SF - PLOMERÍA RODRIGO M04
A2: MES BASE ACTUALIZACIÓN | C2: 46113
A3: MONTO DE OBRA INICIAL | C3: =RESUMEN!D11 -> 9056250
A4: ANTICIPO | D4: =C4/C3 -> 0
F5: NOVIEMBRE | H5: DICIEMBRE | J5: ENERO | L5: FEBRERO | N5: MARZO | P5: ABRIL | R5: MAYO | T5: JUNIO | V5: JULIO | X5: AGOSTO | Z5: SEPTIEMBRE | AB5: OCTUBRE | AD5: NOVIEMBRE | AF5: DICIEMBRE
A6: ITEM | B6: DESCRIPCIÓN | C6: % ITEM | D6: MONTO TOTAL | E6: FINALIZADO | F6: C1 | H6: C2 | J6: C3 | L6: C4 | N6: C5 | P6: C6 | R6: C7 | T6: C8 | V6: C9 | X6: C10 | Z6: C11 | AB6: C12 | AD6: C13 | AF6: C14
A7: 1 | B7: AGUA | C7: =SUM(C8:C12) -> 0.25 | D7: =C7*C3 -> 2264062.5 | F7: Q1 | G7: Q2 | H7: Q1 | I7: Q2 | J7: Q1 | K7: Q2 | L7: Q1 | M7: Q2 | N7: Q1 | O7: Q2 | P7: Q1 | Q7: Q2 | R7: Q1 | S7: Q2 | T7: Q1 | U7: Q2 | V7: Q1 | W7: Q2 | X7: Q1 | Y7: Q2 | Z7: Q3 | AA7: Q4 | AB7: Q5 | AC7: Q6 | AD7: Q7 | AE7: Q8 | AF7: Q9 | AG7: Q10
A8: 1 | B8: 2/4 ambs | C8: 0.05 | E8: =SUM(F8:AG8) -> 0
A9: 2 | B9: Acceso duplex | C9: 0.05 | E9: =SUM(F9:AG9) -> 0
A10: 3 | B10: Estar | C10: 0.05 | E10: =SUM(F10:AG10) -> 0
A11: 4 | B11: Baño dormi 1 | C11: 0.05 | E11: =SUM(F11:AG11) -> 0
A12: 5 | B12: Baño dormi 2 | C12: 0.05 | E12: =SUM(F12:AG12) -> 0
A14: 2 | B14: CLOACALES | C14: =SUM(C15:C19) -> 0.3 | D14: =C14*C3 -> 2716875
A15: 1 | B15: 2/4 ambs | C15: 0.1 | E15: =SUM(F15:AG15) -> 0
A16: 2 | B16: Acceso duplex | C16: 0.05 | E16: =SUM(F16:AG16) -> 0
A17: 3 | B17: Estar | C17: 0.05 | E17: =SUM(F17:AG17) -> 0
A18: 4 | B18: Dormi 1 | C18: 0.05 | E18: =SUM(F18:AG18) -> 0
A19: 5 | B19: Dormi 2 | C19: 0.05 | E19: =SUM(F19:AG19) -> 0
A21: 3 | B21: PLUVIALES | C21: =SUM(C22:C26) -> 0.1 | D21: =C21*C3 -> 905625
A22: 1 | B22: 2/4 ambs | C22: 0.02 | E22: =SUM(F22:AG22) -> 0
A23: 2 | B23: Acceso duplex | C23: 0.02 | E23: =SUM(F23:AG23) -> 0
A24: 3 | B24: Estar | C24: 0.02 | E24: =SUM(F24:AG24) -> 0
A25: 4 | B25: Dormi 1 | C25: 0.02 | E25: =SUM(F25:AG25) -> 0
A26: 5 | B26: Dormi 2 | C26: 0.02 | E26: =SUM(F26:AG26) -> 0
A28: 4 | B28: COLOCACIÓN | C28: =SUM(C29:C33) -> 0.1 | D28: =C28*C3 -> 905625
A29: 1 | B29: 2/4 ambs | C29: 0.02 | E29: =SUM(F29:AG29) -> 0
A30: 2 | B30: Acceso duplex | C30: 0.02 | E30: =SUM(F30:AG30) -> 0
A31: 3 | B31: Estar | C31: 0.02 | E31: =SUM(F31:AG31) -> 0
A32: 4 | B32: Dormi 1 | C32: 0.02 | E32: =SUM(F32:AG32) -> 0
A33: 5 | B33: Dormi 2 | C33: 0.02 | E33: =SUM(F33:AG33) -> 0
A35: 5 | B35: GAS | C35: =SUM(C36) -> 0.08 | D35: =C35*C3 -> 724500
A36: 1 | B36: General | C36: 0.08 | E36: =SUM(F36:AG36) -> 0
A38: 6 | B38: CALEFACCIÓN | C38: =SUM(C39:C43) -> 0.1 | D38: =C38*C3 -> 905625
A39: 1 | B39: 2/4 ambs | C39: 0.02 | E39: =SUM(F39:AG39) -> 0
A40: 2 | B40: Acceso duplex | C40: 0.02 | E40: =SUM(F40:AG40) -> 0
A41: 3 | B41: Estar | C41: 0.02 | E41: =SUM(F41:AG41) -> 0
A42: 4 | B42: Dormi 1 | C42: 0.02 | E42: =SUM(F42:AG42) -> 0
A43: 5 | B43: Dormi 2 | C43: 0.02 | E43: =SUM(F43:AG43) -> 0
A45: 7 | B45: ESPECIALES | C45: =SUM(C46:C49) -> 0.07 | D45: =C45*C3 -> 633937.5
A46: 1 | B46: Bacha parrilla | C46: 0.02 | E46: =SUM(F46:AG46) -> 0
...

Sheet M03
B1: SF - PLOMERÍA RODRIGO M03
A2: MES BASE ACTUALIZACIÓN | C2: 46113
A3: MONTO DE OBRA INICIAL | C3: =RESUMEN!D11 -> 9056250
A4: ANTICIPO | D4: =C4/C3 -> 0
F5: NOVIEMBRE | H5: DICIEMBRE | J5: ENERO | L5: FEBRERO | N5: MARZO | P5: ABRIL | R5: MAYO | T5: JUNIO | V5: JULIO | X5: AGOSTO | Z5: SEPTIEMBRE | AB5: OCTUBRE | AD5: NOVIEMBRE | AF5: DICIEMBRE
A6: ITEM | B6: DESCRIPCIÓN | C6: % ITEM | D6: MONTO TOTAL | E6: FINALIZADO | F6: C1 | H6: C2 | J6: C3 | L6: C4 | N6: C5 | P6: C6 | R6: C7 | T6: C8 | V6: C9 | X6: C10 | Z6: C11 | AB6: C12 | AD6: C13 | AF6: C14
A7: 1 | B7: AGUA | C7: =SUM(C8:C12) -> 0.25 | D7: =C7*C3 -> 2264062.5 | F7: Q1 | G7: Q2 | H7: Q1 | I7: Q2 | J7: Q1 | K7: Q2 | L7: Q1 | M7: Q2 | N7: Q1 | O7: Q2 | P7: Q1 | Q7: Q2 | R7: Q1 | S7: Q2 | T7: Q1 | U7: Q2 | V7: Q1 | W7: Q2 | X7: Q1 | Y7: Q2 | Z7: Q3 | AA7: Q4 | AB7: Q5 | AC7: Q6 | AD7: Q7 | AE7: Q8 | AF7: Q9 | AG7: Q10
A8: 1 | B8: 2/4 ambs | C8: 0.05 | E8: =SUM(F8:AG8) -> 0
A9: 2 | B9: Acceso duplex | C9: 0.05 | E9: =SUM(F9:AG9) -> 0
A10: 3 | B10: Estar | C10: 0.05 | E10: =SUM(F10:AG10) -> 0
A11: 4 | B11: Baño dormi 1 | C11: 0.05 | E11: =SUM(F11:AG11) -> 0
A12: 5 | B12: Baño dormi 2 | C12: 0.05 | E12: =SUM(F12:AG12) -> 0
A14: 2 | B14: CLOACALES | C14: =SUM(C15:C19) -> 0.3 | D14: =C14*C3 -> 2716875
A15: 1 | B15: 2/4 ambs | C15: 0.1 | E15: =SUM(F15:AG15) -> 0
A16: 2 | B16: Acceso duplex | C16: 0.05 | E16: =SUM(F16:AG16) -> 0
A17: 3 | B17: Estar | C17: 0.05 | E17: =SUM(F17:AG17) -> 0
A18: 4 | B18: Dormi 1 | C18: 0.05 | E18: =SUM(F18:AG18) -> 0
A19: 5 | B19: Dormi 2 | C19: 0.05 | E19: =SUM(F19:AG19) -> 0
A21: 3 | B21: PLUVIALES | C21: =SUM(C22:C26) -> 0.1 | D21: =C21*C3 -> 905625
A22: 1 | B22: 2/4 ambs | C22: 0.02 | E22: =SUM(F22:AG22) -> 0
A23: 2 | B23: Acceso duplex | C23: 0.02 | E23: =SUM(F23:AG23) -> 0
A24: 3 | B24: Estar | C24: 0.02 | E24: =SUM(F24:AG24) -> 0
A25: 4 | B25: Dormi 1 | C25: 0.02 | E25: =SUM(F25:AG25) -> 0
A26: 5 | B26: Dormi 2 | C26: 0.02 | E26: =SUM(F26:AG26) -> 0
A28: 4 | B28: COLOCACIÓN | C28: =SUM(C29:C33) -> 0.1 | D28: =C28*C3 -> 905625
A29: 1 | B29: 2/4 ambs | C29: 0.02 | E29: =SUM(F29:AG29) -> 0
A30: 2 | B30: Acceso duplex | C30: 0.02 | E30: =SUM(F30:AG30) -> 0
A31: 3 | B31: Estar | C31: 0.02 | E31: =SUM(F31:AG31) -> 0
A32: 4 | B32: Dormi 1 | C32: 0.02 | E32: =SUM(F32:AG32) -> 0
A33: 5 | B33: Dormi 2 | C33: 0.02 | E33: =SUM(F33:AG33) -> 0
A35: 5 | B35: GAS | C35: =SUM(C36) -> 0.08 | D35: =C35*C3 -> 724500
A36: 1 | B36: General | C36: 0.08 | E36: =SUM(F36:AG36) -> 0
A38: 6 | B38: CALEFACCIÓN | C38: =SUM(C39:C43) -> 0.1 | D38: =C38*C3 -> 905625
A39: 1 | B39: 2/4 ambs | C39: 0.02 | E39: =SUM(F39:AG39) -> 0
A40: 2 | B40: Acceso duplex | C40: 0.02 | E40: =SUM(F40:AG40) -> 0
A41: 3 | B41: Estar | C41: 0.02 | E41: =SUM(F41:AG41) -> 0
A42: 4 | B42: Dormi 1 | C42: 0.02 | E42: =SUM(F42:AG42) -> 0
A43: 5 | B43: Dormi 2 | C43: 0.02 | E43: =SUM(F43:AG43) -> 0
A45: 7 | B45: ESPECIALES | C45: =SUM(C46:C49) -> 0.07 | D45: =C45*C3 -> 633937.5
A46: 1 | B46: Bacha parrilla | C46: 0.02 | E46: =SUM(F46:AG46) -> 0
...

Sheet M02
B1: SF - PLOMERÍA RODRIGO M02
A2: MES BASE ACTUALIZACIÓN | C2: 46113
A3: MONTO DE OBRA INICIAL | C3: =RESUMEN!D11 -> 9056250
A4: ANTICIPO | D4: =C4/C3 -> 0
F5: FEBRERO | H5: MARZO | J5: ABRIL | L5: MAYO | N5: JUNIO | P5: JULIO | R5: AGOSTO | T5: SEPTIEMBRE | V5: OCTUBRE | X5: NOVIEMBRE | Z5: DICIEMBRE | AB5: ENERO | AD5: FEBRERO | AF5: MARZO
A6: ITEM | B6: DESCRIPCIÓN | C6: % ITEM | D6: MONTO TOTAL | E6: FINALIZADO | F6: C1 | H6: C2 | J6: C3 | L6: C4 | N6: C5 | P6: C6 | R6: C7 | T6: C8 | V6: C9 | X6: C10 | Z6: C11 | AB6: C12 | AD6: C13 | AF6: C14
A7: 1 | B7: AGUA | C7: =SUM(C8:C12) -> 0.25 | D7: =C7*C3 -> 2264062.5 | F7: Q1 | G7: Q2 | H7: Q1 | I7: Q2 | J7: Q1 | K7: Q2 | L7: Q1 | M7: Q2 | N7: Q1 | O7: Q2 | P7: Q1 | Q7: Q2 | R7: Q1 | S7: Q2 | T7: Q1 | U7: Q2 | V7: Q1 | W7: Q2 | X7: Q1 | Y7: Q2 | Z7: Q3 | AA7: Q4 | AB7: Q5 | AC7: Q6 | AD7: Q7 | AE7: Q8 | AF7: Q9 | AG7: Q10
A8: 1 | B8: 2/4 ambs | C8: 0.05 | E8: =SUM(F8:AG8) -> 0
A9: 2 | B9: Acceso duplex | C9: 0.05 | E9: =SUM(F9:AG9) -> 0
A10: 3 | B10: Estar | C10: 0.05 | E10: =SUM(F10:AG10) -> 0
A11: 4 | B11: Baño dormi 1 | C11: 0.05 | E11: =SUM(F11:AG11) -> 0
A12: 5 | B12: Baño dormi 2 | C12: 0.05 | E12: =SUM(F12:AG12) -> 0
A14: 2 | B14: CLOACALES | C14: =SUM(C15:C19) -> 0.3 | D14: =C14*C3 -> 2716875
A15: 1 | B15: 2/4 ambs | C15: 0.1 | E15: =SUM(F15:AG15) -> 0
A16: 2 | B16: Acceso duplex | C16: 0.05 | E16: =SUM(F16:AG16) -> 0
A17: 3 | B17: Estar | C17: 0.05 | E17: =SUM(F17:AG17) -> 0
A18: 4 | B18: Dormi 1 | C18: 0.05 | E18: =SUM(F18:AG18) -> 0
A19: 5 | B19: Dormi 2 | C19: 0.05 | E19: =SUM(F19:AG19) -> 0
A21: 3 | B21: PLUVIALES | C21: =SUM(C22:C26) -> 0.1 | D21: =C21*C3 -> 905625
A22: 1 | B22: 2/4 ambs | C22: 0.02 | E22: =SUM(F22:AG22) -> 0
A23: 2 | B23: Acceso duplex | C23: 0.02 | E23: =SUM(F23:AG23) -> 0
A24: 3 | B24: Estar | C24: 0.02 | E24: =SUM(F24:AG24) -> 0
A25: 4 | B25: Dormi 1 | C25: 0.02 | E25: =SUM(F25:AG25) -> 0
A26: 5 | B26: Dormi 2 | C26: 0.02 | E26: =SUM(F26:AG26) -> 0
A28: 4 | B28: COLOCACIÓN | C28: =SUM(C29:C33) -> 0.1 | D28: =C28*C3 -> 905625
A29: 1 | B29: 2/4 ambs | C29: 0.02 | E29: =SUM(F29:AG29) -> 0
A30: 2 | B30: Acceso duplex | C30: 0.02 | E30: =SUM(F30:AG30) -> 0
A31: 3 | B31: Estar | C31: 0.02 | E31: =SUM(F31:AG31) -> 0
A32: 4 | B32: Dormi 1 | C32: 0.02 | E32: =SUM(F32:AG32) -> 0
A33: 5 | B33: Dormi 2 | C33: 0.02 | E33: =SUM(F33:AG33) -> 0
A35: 5 | B35: GAS | C35: =SUM(C36) -> 0.08 | D35: =C35*C3 -> 724500
A36: 1 | B36: General | C36: 0.08 | E36: =SUM(F36:AG36) -> 0
A38: 6 | B38: CALEFACCIÓN | C38: =SUM(C39:C43) -> 0.1 | D38: =C38*C3 -> 905625
A39: 1 | B39: 2/4 ambs | C39: 0.02 | E39: =SUM(F39:AG39) -> 0
A40: 2 | B40: Acceso duplex | C40: 0.02 | E40: =SUM(F40:AG40) -> 0
A41: 3 | B41: Estar | C41: 0.02 | E41: =SUM(F41:AG41) -> 0
A42: 4 | B42: Dormi 1 | C42: 0.02 | E42: =SUM(F42:AG42) -> 0
A43: 5 | B43: Dormi 2 | C43: 0.02 | E43: =SUM(F43:AG43) -> 0
A45: 7 | B45: ESPECIALES | C45: =SUM(C46:C49) -> 0.07 | D45: =C45*C3 -> 633937.5
A46: 1 | B46: Bacha parrilla | C46: 0.02 | E46: =SUM(F46:AG46) -> 0
...

Sheet M01
B1: SF - PLOMERÍA RODRIGO M01
A2: MES BASE ACTUALIZACIÓN | C2: 46113
A3: MONTO DE OBRA INICIAL | C3: =RESUMEN!D11 -> 9056250
A4: ANTICIPO | D4: =C4/C3 -> 0
F5: FEBRERO | H5: MARZO | J5: ABRIL | L5: MAYO | N5: JUNIO | P5: JULIO | R5: AGOSTO | T5: SEPTIEMBRE | V5: OCTUBRE | X5: NOVIEMBRE | Z5: DICIEMBRE | AB5: ENERO | AD5: FEBRERO | AF5: MARZO
A6: ITEM | B6: DESCRIPCIÓN | C6: % ITEM | D6: MONTO TOTAL | E6: FINALIZADO | F6: C1 | H6: C2 | J6: C3 | L6: C4 | N6: C5 | P6: C6 | R6: C7 | T6: C8 | V6: C9 | X6: C10 | Z6: C11 | AB6: C12 | AD6: C13 | AF6: C14
A7: 1 | B7: AGUA | C7: =SUM(C8:C12) -> 0.25 | D7: =C7*C3 -> 2264062.5 | F7: Q1 | G7: Q2 | H7: Q1 | I7: Q2 | J7: Q1 | K7: Q2 | L7: Q1 | M7: Q2 | N7: Q1 | O7: Q2 | P7: Q1 | Q7: Q2 | R7: Q1 | S7: Q2 | T7: Q1 | U7: Q2 | V7: Q1 | W7: Q2 | X7: Q1 | Y7: Q2 | Z7: Q3 | AA7: Q4 | AB7: Q5 | AC7: Q6 | AD7: Q7 | AE7: Q8 | AF7: Q9 | AG7: Q10
A8: 1 | B8: 2/4 ambs | C8: 0.05 | E8: =SUM(F8:AG8) -> 0
A9: 2 | B9: Acceso duplex | C9: 0.05 | E9: =SUM(F9:AG9) -> 0
A10: 3 | B10: Estar | C10: 0.05 | E10: =SUM(F10:AG10) -> 0
A11: 4 | B11: Baño dormi 1 | C11: 0.05 | E11: =SUM(F11:AG11) -> 0
A12: 5 | B12: Baño dormi 2 | C12: 0.05 | E12: =SUM(F12:AG12) -> 0
A14: 2 | B14: CLOACALES | C14: =SUM(C15:C19) -> 0.3 | D14: =C14*C3 -> 2716875
A15: 1 | B15: 2/4 ambs | C15: 0.1 | E15: =SUM(F15:AG15) -> 0
A16: 2 | B16: Acceso duplex | C16: 0.05 | E16: =SUM(F16:AG16) -> 0
A17: 3 | B17: Estar | C17: 0.05 | E17: =SUM(F17:AG17) -> 0
A18: 4 | B18: Dormi 1 | C18: 0.05 | E18: =SUM(F18:AG18) -> 0
A19: 5 | B19: Dormi 2 | C19: 0.05 | E19: =SUM(F19:AG19) -> 0
A21: 3 | B21: PLUVIALES | C21: =SUM(C22:C26) -> 0.1 | D21: =C21*C3 -> 905625
A22: 1 | B22: 2/4 ambs | C22: 0.02 | E22: =SUM(F22:AG22) -> 0
A23: 2 | B23: Acceso duplex | C23: 0.02 | E23: =SUM(F23:AG23) -> 0
A24: 3 | B24: Estar | C24: 0.02 | E24: =SUM(F24:AG24) -> 0
A25: 4 | B25: Dormi 1 | C25: 0.02 | E25: =SUM(F25:AG25) -> 0
A26: 5 | B26: Dormi 2 | C26: 0.02 | E26: =SUM(F26:AG26) -> 0
A28: 4 | B28: COLOCACIÓN | C28: =SUM(C29:C33) -> 0.1 | D28: =C28*C3 -> 905625
A29: 1 | B29: 2/4 ambs | C29: 0.02 | E29: =SUM(F29:AG29) -> 0
A30: 2 | B30: Acceso duplex | C30: 0.02 | E30: =SUM(F30:AG30) -> 0
A31: 3 | B31: Estar | C31: 0.02 | E31: =SUM(F31:AG31) -> 0
A32: 4 | B32: Dormi 1 | C32: 0.02 | E32: =SUM(F32:AG32) -> 0
A33: 5 | B33: Dormi 2 | C33: 0.02 | E33: =SUM(F33:AG33) -> 0
A35: 5 | B35: GAS | C35: =SUM(C36) -> 0.08 | D35: =C35*C3 -> 724500
A36: 1 | B36: General | C36: 0.08 | E36: =SUM(F36:AG36) -> 0
A38: 6 | B38: CALEFACCIÓN | C38: =SUM(C39:C43) -> 0.1 | D38: =C38*C3 -> 905625
A39: 1 | B39: 2/4 ambs | C39: 0.02 | E39: =SUM(F39:AG39) -> 0
A40: 2 | B40: Acceso duplex | C40: 0.02 | E40: =SUM(F40:AG40) -> 0
A41: 3 | B41: Estar | C41: 0.02 | E41: =SUM(F41:AG41) -> 0
A42: 4 | B42: Dormi 1 | C42: 0.02 | E42: =SUM(F42:AG42) -> 0
A43: 5 | B43: Dormi 2 | C43: 0.02 | E43: =SUM(F43:AG43) -> 0
A45: 7 | B45: ESPECIALES | C45: =SUM(C46:C49) -> 0.07 | D45: =C45*C3 -> 633937.5
A46: 1 | B46: Bacha parrilla | C46: 0.02 | E46: =SUM(F46:AG46) -> 0
...
